Workbook
Name Slicer_Representative: #N/A

Sheet Sheet2

Sheet Sheet3

Sheet Sheet4
A3: call count | B3: Total amount | C3: Sum of Duration | D3: Avg Satisfaction Rating | E3: Sum of 5 star
A4: 1000 | B4: 96623 | C4: 89850 | D4: 3.8854 | E4: 307
A10: call count | B10: Total amount | C10: Sum of Duration | D10: Avg Satisfaction Rating | E10: Sum of 5 star
A11: 189 | B11: 18415 | C11: 16834 | D11: 3.9227513 | E11: 60
A17: Row Labels | B17: Sum of call count | C17: Sum of call count2
A18: Jan | B18: 16 | C18: 16
A19: Feb | B19: 14 | C19: 14 | G19: Row Labels | H19: Sum of call count
A20: Mar | B20: 26 | C20: 26 | G20: Sunday | H20: 36
A21: Apr | B21: 29 | C21: 29 | G21: Monday | H21: 30
A22: May | B22: 17 | C22: 17 | G22: Tuesday | H22: 13
A23: Jun | B23: 15 | C23: 15 | G23: Wednesday | H23: 23
A24: Jul | B24: 15 | C24: 15 | G24: Thursday | H24: 23
A25: Aug | B25: 7 | C25: 7 | G25: Friday | H25: 24
A26: Sep | B26: 11 | C26: 11 | G26: Saturday | H26: 40
A27: Oct | B27: 24 | C27: 24 | G27: Grand Total | H27: 189
A28: Nov | B28: 9 | C28: 9
A29: Dec | B29: 6 | C29: 6
A30: Grand Total | B30: 189 | C30: 189
A50: Row Labels | B50: Sum of call count | C50: Sum of Purchase Amount | E50: for graphs
A51: R01 | B51: 189 | C51: 18415 | I51: selected rep | J51: =A82 -> R01
A52: R02 | B52: 218 | C52: 20581
A53: R03 | B53: 207 | C53: 20872
A54: R04 | B54: 186 | C54: 16651 | F54: rap | G54: calls | H54: amount | I54: sel.Calls | J54: Sel.Amount
A55: R05 | B55: 200 | C55: 20104 | F55: {=A51:C55} -> R01 | G55: 189 | H55: 18415 | I55: =IF(F55=$J$51,G55,NA()) -> 189 | J55: =IF(F55=$J$51,H55,NA()) -> 18415
A56: Grand Total | B56: 1000 | C56: 96623 | F56: R02 | G56: 218 | H56: 20581 | I56: =IF(F56=$J$51,G56,NA()) -> #N/A | J56: =IF(F56=$J$51,H56,NA()) -> #N/A
F57: R03 | G57: 207 | H57: 20872 | I57: =IF(F57=$J$51,G57,NA()) -> #N/A | J57: =IF(F57=$J$51,H57,NA()) -> #N/A
F58: R04 | G58: 186 | H58: 16651 | I58: =IF(F58=$J$51,G58,NA()) -> #N/A | J58: =IF(F58=$J$51,H58,NA()) -> #N/A
F59: R05 | G59: 200 | H59: 20104 | I59: =IF(F59=$J$51,G59,NA()) -> #N/A | J59: =IF(F59=$J$51,H59,NA()) -> #N/A
A68: #VALUE!
H69: Rep Summary
H71: % of calls | I71: =A11/A4 -> 0.189
H72: Calls | I72: =_xlfn.XLOOKUP(A82,F55:F59,G55:G59) -> 189
H73: Amount rank | I73: =_xlfn.XLOOKUP(A82,F55:F59,H55:H59) -> 18415
H74: call rank | I74: =_xlfn.RANK.AVG(I72,G55:G59) -> 4
H75: Amount rank | I75: =_xlfn.RANK.AVG(I73,H55:H59) -> 4
H77: labels:
I78: ="% of calls:"&TEXT(I71,"0%") -> % of calls:19%
I79: =IF(COUNTA(A82:A86)>1,"","call rank:"&I74) -> call rank:4
I80: ="Amount rank:"&I75 -> Amount rank:4
A81: Row Labels
...

Sheet Data
B1: Call Centre Data
B3: Call number | C3: Customer ID | D3: Duration | E3: Representative | F3: Date of Call | G3: Purchase Amount | H3: Satisfaction Rating | I3: FY | J3: Day of week | K3: Duration Bucket | L3: Rating rounded | M3: City | N3: Gedner | O3: Age | P3: call count | Q3: 5 star | R3: Customer ID | S3: Gedner | T3: Age | U3: City
B4: Call_7271 | C4: C0003 | D4: 116 | E4: R05 | F4: 44927 | G4: 128 | H4: 4.9 | I4: =IF(MONTH(calls[[#This Row],[Date of Call]])<=6, YEAR(calls[[#This Row],[Date of Call]]), YEAR(calls[[#This Row],[Date of Call]])+1) -> 2023 | J4: =TEXT(calls[[#This Row],[Date of Call]],"DDDD") -> Sunday | K4: {=_xlfn.IFS(calls[[#This Row],[Duration]]<=10,"Under 10 mins", calls[[#This Row],[Duration]]<=30, "10 to 30 mins", calls[[#This Row],[Duration]]<=60, "30 to 60 mins", calls[[#This Row],[Duration]]<=120, "1 to 2 hours", TRUE, "More than 2 hours")} -> 1 to 2 hours | L4: =ROUND(calls[[#This Row],[Satisfaction Rating]],0) -> 5 | M4: =_xlfn.XLOOKUP(calls[[#This Row],[Customer ID]],customers[Customer ID],customers[City]) -> Cincinnati | N4: =_xlfn.XLOOKUP(calls[[#This Row],[Customer ID]],customers[Customer ID],customers[Gedner]) -> Male | O4: 41 | P4: =IF(calls[[#This Row],[Call number]]<>"",1,0) -> 1 | Q4: =IF(calls[[#This Row],[Rating rounded]]=5,1,0) -> 1 | R4: C0001 | S4: Male | T4: 41 | U4: Columbus
B5: Call_7272 | C5: C0004 | D5: 119 | E5: R05 | F5: 44927 | G5: 135 | H5: 2.9 | I5: =IF(MONTH(calls[[#This Row],[Date of Call]])<=6, YEAR(calls[[#This Row],[Date of Call]]), YEAR(calls[[#This Row],[Date of Call]])+1) -> 2023 | J5: =TEXT(calls[[#This Row],[Date of Call]],"DDDD") -> Sunday | K5: {=_xlfn.IFS(calls[[#This Row],[Duration]]<=10,"Under 10 mins", calls[[#This Row],[Duration]]<=30, "10 to 30 mins", calls[[#This Row],[Duration]]<=60, "30 to 60 mins", calls[[#This Row],[Duration]]<=120, "1 to 2 hours", TRUE, "More than 2 hours")} -> 1 to 2 hours | L5: =ROUND(calls[[#This Row],[Satisfaction Rating]],0) -> 3 | M5: =_xlfn.XLOOKUP(calls[[#This Row],[Customer ID]],customers[Customer ID],customers[City]) -> Cincinnati | N5: =_xlfn.XLOOKUP(calls[[#This Row],[Customer ID]],customers[Customer ID],customers[Gedner]) -> Male | O5: 31 | P5: =IF(calls[[#This Row],[Call number]]<>"",1,0) -> 1 | Q5: =IF(calls[[#This Row],[Rating rounded]]=5,1,0) -> 0 | R5: C0002 | S5: Male | T5: 31 | U5: Cleveland
B6: Call_7273 | C6: C0005 | D6: 68 | E6: R02 | F6: 44927 | G6: 66 | H6: 4.7 | I6: =IF(MONTH(calls[[#This Row],[Date of Call]])<=6, YEAR(calls[[#This Row],[Date of Call]]), YEAR(calls[[#This Row],[Date of Call]])+1) -> 2023 | J6: =TEXT(calls[[#This Row],[Date of Call]],"DDDD") -> Sunday | K6: {=_xlfn.IFS(calls[[#This Row],[Duration]]<=10,"Under 10 mins", calls[[#This Row],[Duration]]<=30, "10 to 30 mins", calls[[#This Row],[Duration]]<=60, "30 to 60 mins", calls[[#This Row],[Duration]]<=120, "1 to 2 hours", TRUE, "More than 2 hours")} -> 1 to 2 hours | L6: =ROUND(calls[[#This Row],[Satisfaction Rating]],0) -> 5 | M6: =_xlfn.XLOOKUP(calls[[#This Row],[Customer ID]],customers[Customer ID],customers[City]) -> Columbus | N6: =_xlfn.XLOOKUP(calls[[#This Row],[Customer ID]],customers[Customer ID],customers[Gedner]) -> Male | O6: 26 | P6: =IF(calls[[#This Row],[Call number]]<>"",1,0) -> 1 | Q6: =IF(calls[[#This Row],[Rating rounded]]=5,1,0) -> 1 | R6: C0003 | S6: Male | T6: 26 | U6: Cincinnati
B7: Call_7274 | C7: C0014 | D7: 119 | E7: R02 | F7: 44927 | G7: 22 | H7: 2.9 | I7: =IF(MONTH(calls[[#This Row],[Date of Call]])<=6, YEAR(calls[[#This Row],[Date of Call]]), YEAR(calls[[#This Row],[Date of Call]])+1) -> 2023 | J7: =TEXT(calls[[#This Row],[Date of Call]],"DDDD") -> Sunday | K7: {=_xlfn.IFS(calls[[#This Row],[Duration]]<=10,"Under 10 mins", calls[[#This Row],[Duration]]<=30, "10 to 30 mins", calls[[#This Row],[Duration]]<=60, "30 to 60 mins", calls[[#This Row],[Duration]]<=120, "1 to 2 hours", TRUE, "More than 2 hours")} -> 1 to 2 hours | L7: =ROUND(calls[[#This Row],[Satisfaction Rating]],0) -> 3 | M7: =_xlfn.XLOOKUP(calls[[#This Row],[Customer ID]],customers[Customer ID],customers[City]) -> Columbus | N7: =_xlfn.XLOOKUP(calls[[#This Row],[Customer ID]],customers[Customer ID],customers[Gedner]) -> Female | O7: 36 | P7: =IF(calls[[#This Row],[Call number]]<>"",1,0) -> 1 | Q7: =IF(calls[[#This Row],[Rating rounded]]=5,1,0) -> 0 | R7: C0004 | S7: Male | T7: 36 | U7: Cincinnati
B8: Call_7275 | C8: C0011 | D8: 128 | E8: R01 | F8: 44928 | G8: 31 | H8: 2.8 | I8: =IF(MONTH(calls[[#This Row],[Date of Call]])<=6, YEAR(calls[[#This Row],[Date of Call]]), YEAR(calls[[#This Row],[Date of Call]])+1) -> 2023 | J8: =TEXT(calls[[#This Row],[Date of Call]],"DDDD") -> Monday | K8: {=_xlfn.IFS(calls[[#This Row],[Duration]]<=10,"Under 10 mins", calls[[#This Row],[Duration]]<=30, "10 to 30 mins", calls[[#This Row],[Duration]]<=60, "30 to 60 mins", calls[[#This Row],[Duration]]<=120, "1 to 2 hours", TRUE, "More than 2 hours")} -> More than 2 hours | L8: =ROUND(calls[[#This Row],[Satisfaction Rating]],0) -> 3 | M8: =_xlfn.XLOOKUP(calls[[#This Row],[Customer ID]],customers[Customer ID],customers[City]) -> Cincinnati | N8: =_xlfn.XLOOKUP(calls[[#This Row],[Customer ID]],customers[Customer ID],customers[Gedner]) -> Female | O8: 37 | P8: =IF(calls[[#This Row],[Call number]]<>"",1,0) -> 1 | Q8: =IF(calls[[#This Row],[Rating rounded]]=5,1,0) -> 0 | R8: C0005 | S8: Male | T8: 37 | U8: Columbus
B9: Call_7276 | C9: C0011 | D9: 49 | E9: R02 | F9: 44929 | G9: 135 | H9: 4.8 | I9: =IF(MONTH(calls[[#This Row],[Date of Call]])<=6, YEAR(calls[[#This Row],[Date of Call]]), YEAR(calls[[#This Row],[Date of Call]])+1) -> 2023 | J9: =TEXT(calls[[#This Row],[Date of Call]],"DDDD") -> Tuesday | K9: {=_xlfn.IFS(calls[[#This Row],[Duration]]<=10,"Under 10 mins", calls[[#This Row],[Duration]]<=30, "10 to 30 mins", calls[[#This Row],[Duration]]<=60, "30 to 60 mins", calls[[#This Row],[Duration]]<=120, "1 to 2 hours", TRUE, "More than 2 hours")} -> 30 to 60 mins | L9: =ROUND(calls[[#This Row],[Satisfaction Rating]],0) -> 5 | M9: =_xlfn.XLOOKUP(calls[[#This Row],[Customer ID]],customers[Customer ID],customers[City]) -> Cincinnati | N9: =_xlfn.XLOOKUP(calls[[#This Row],[Customer ID]],customers[Customer ID],customers[Gedner]) -> Female | O9: 23 | P9: =IF(calls[[#This Row],[Call number]]<>"",1,0) -> 1 | Q9: =IF(calls[[#This Row],[Rating rounded]]=5,1,0) -> 1 | R9: C0006 | S9: Male | T9: 23 | U9: Columbus
B10: Call_7277 | C10: C0007 | D10: 84 | E10: R05 | F10: 44929 | G10: 60 | H10: 4.7 | I10: =IF(MONTH(calls[[#This Row],[Date of Call]])<=6, YEAR(calls[[#This Row],[Date of Call]]), YEAR(calls[[#This Row],[Date of Call]])+1) -> 2023 | J10: =TEXT(calls[[#This Row],[Date of Call]],"DDDD") -> Tuesday | K10: {=_xlfn.IFS(calls[[#This Row],[Duration]]<=10,"Under 10 mins", calls[[#This Row],[Duration]]<=30, "10 to 30 mins", calls[[#This Row],[Duration]]<=60, "30 to 60 mins", calls[[#This Row],[Duration]]<=120, "1 to 2 hours", TRUE, "More than 2 hours")} -> 1 to 2 hours | L10: =ROUND(calls[[#This Row],[Satisfaction Rating]],0) -> 5 | M10: =_xlfn.XLOOKUP(calls[[#This Row],[Customer ID]],customers[Customer ID],customers[City]) -> Cleveland | N10: =_xlfn.XLOOKUP(calls[[#This Row],[Customer ID]],customers[Customer ID],customers[Gedner]) -> Female | O10: 22 | P10: =IF(calls[[#This Row],[Call number]]<>"",1,0) -> 1 | Q10: =IF(calls[[#This Row],[Rating rounded]]=5,1,0) -> 1 | R10: C0007 | S10: Female | T10: 22 | U10: Cleveland
B11: Call_7278 | C11: C0003 | D11: 103 | E11: R04 | F11: 44929 | G11: 148 | H11: 4.4 | I11: =IF(MONTH(calls[[#This Row],[Date of Call]])<=6, YEAR(calls[[#This Row],[Date of Call]]), YEAR(calls[[#This Row],[Date of Call]])+1) -> 2023 | J11: =TEXT(calls[[#This Row],[Date of Call]],"DDDD") -> Tuesday | K11: {=_xlfn.IFS(calls[[#This Row],[Duration]]<=10,"Under 10 mins", calls[[#This Row],[Duration]]<=30, "10 to 30 mins", calls[[#This Row],[Duration]]<=60, "30 to 60 mins", calls[[#This Row],[Duration]]<=120, "1 to 2 hours", TRUE, "More than 2 hours")} -> 1 to 2 hours | L11: =ROUND(calls[[#This Row],[Satisfaction Rating]],0) -> 4 | M11: =_xlfn.XLOOKUP(calls[[#This Row],[Customer ID]],customers[Customer ID],customers[City]) -> Cincinnati | N11: =_xlfn.XLOOKUP(calls[[#This Row],[Customer ID]],customers[Customer ID],customers[Gedner]) -> Male | O11: 42 | P11: =IF(calls[[#This Row],[Call number]]<>"",1,0) -> 1 | Q11: =IF(calls[[#This Row],[Rating rounded]]=5,1,0) -> 0 | R11: C0008 | S11: Female | T11: 42 | U11: Cleveland
B12: Call_7279 | C12: C0005 | D12: 31 | E12: R02 | F12: 44929 | G12: 135 | H12: 3.6 | I12: =IF(MONTH(calls[[#This Row],[Date of Call]])<=6, YEAR(calls[[#This Row],[Date of Call]]), YEAR(calls[[#This Row],[Date of Call]])+1) -> 2023 | J12: =TEXT(calls[[#This Row],[Date of Call]],"DDDD") -> Tuesday | K12: {=_xlfn.IFS(calls[[#This Row],[Duration]]<=10,"Under 10 mins", calls[[#This Row],[Duration]]<=30, "10 to 30 mins", calls[[#This Row],[Duration]]<=60, "30 to 60 mins", calls[[#This Row],[Duration]]<=120, "1 to 2 hours", TRUE, "More than 2 hours")} -> 30 to 60 mins | L12: =ROUND(calls[[#This Row],[Satisfaction Rating]],0) -> 4 | M12: =_xlfn.XLOOKUP(calls[[#This Row],[Customer ID]],customers[Customer ID],customers[City]) -> Columbus | N12: =_xlfn.XLOOKUP(calls[[#This Row],[Customer ID]],customers[Customer ID],customers[Gedner]) -> Male | O12: 25 | P12: =IF(calls[[#This Row],[Call number]]<>"",1,0) -> 1 | Q12: =IF(calls[[#This Row],[Rating rounded]]=5,1,0) -> 0 | R12: C0009 | S12: Female | T12: 25 | U12: Columbus
B13: Call_7280 | C13: C0010 | D13: 44 | E13: R03 | F13: 44929 | G13: 105 | H13: 2.9 | I13: =IF(MONTH(calls[[#This Row],[Date of Call]])<=6, YEAR(calls[[#This Row],[Date of Call]]), YEAR(calls[[#This Row],[Date of Call]])+1) -> 2023 | J13: =TEXT(calls[[#This Row],[Date of Call]],"DDDD") -> Tuesday | K13: {=_xlfn.IFS(calls[[#This Row],[Duration]]<=10,"Under 10 mins", calls[[#This Row],[Duration]]<=30, "10 to 30 mins", calls[[#This Row],[Duration]]<=60, "30 to 60 mins", calls[[#This Row],[Duration]]<=120, "1 to 2 hours", TRUE, "More than 2 hours")} -> 30 to 60 mins | L13: =ROUND(calls[[#This Row],[Satisfaction Rating]],0) -> 3 | M13: =_xlfn.XLOOKUP(calls[[#This Row],[Customer ID]],customers[Customer ID],customers[City]) -> Cleveland | N13: =_xlfn.XLOOKUP(calls[[#This Row],[Customer ID]],customers[Customer ID],customers[Gedner]) -> Female | O13: 30 | P13: =IF(calls[[#This Row],[Call number]]<>"",1,0) -> 1 | Q13: =IF(calls[[#This Row],[Rating rounded]]=5,1,0) -> 0 | R13: C0010 | S13: Female | T13: 30 | U13: Cleveland
B14: Call_7281 | C14: C0011 | D14: 102 | E14: R02 | F14: 44929 | G14: 69 | H14: 4.9 | I14: =IF(MONTH(calls[[#This Row],[Date of Call]])<=6, YEAR(calls[[#This Row],[Date of Call]]), YEAR(calls[[#This Row],[Date of Call]])+1) -> 2023 | J14: =TEXT(calls[[#This Row],[Date of Call]],"DDDD") -> Tuesday | K14: {=_xlfn.IFS(calls[[#This Row],[Duration]]<=10,"Under 10 mins", calls[[#This Row],[Duration]]<=30, "10 to 30 mins", calls[[#This Row],[Duration]]<=60, "30 to 60 mins", calls[[#This Row],[Duration]]<=120, "1 to 2 hours", TRUE, "More than 2 hours")} -> 1 to 2 hours | L14: =ROUND(calls[[#This Row],[Satisfaction Rating]],0) -> 5 | M14: =_xlfn.XLOOKUP(calls[[#This Row],[Customer ID]],customers[Customer ID],customers[City]) -> Cincinnati | N14: =_xlfn.XLOOKUP(calls[[#This Row],[Customer ID]],customers[Customer ID],customers[Gedner]) -> Female | O14: 30 | P14: =IF(calls[[#This Row],[Call number]]<>"",1,0) -> 1 | Q14: =IF(calls[[#This Row],[Rating rounded]]=5,1,0) -> 1 | R14: C0011 | S14: Female | T14: 30 | U14: Cincinnati
B15: Call_7282 | C15: C0013 | D15: 135 | E15: R05 | F15: 44929 | G15: 46 | H15: 3.4 | I15: =IF(MONTH(calls[[#This Row],[Date of Call]])<=6, YEAR(calls[[#This Row],[Date of Call]]), YEAR(calls[[#This Row],[Date of Call]])+1) -> 2023 | J15: =TEXT(calls[[#This Row],[Date of Call]],"DDDD") -> Tuesday | K15: {=_xlfn.IFS(calls[[#This Row],[Duration]]<=10,"Under 10 mins", calls[[#This Row],[Duration]]<=30, "10 to 30 mins", calls[[#This Row],[Duration]]<=60, "30 to 60 mins", calls[[#This Row],[Duration]]<=120, "1 to 2 hours", TRUE, "More than 2 hours")} -> More than 2 hours | L15: =ROUND(calls[[#This Row],[Satisfaction Rating]],0) -> 3 | M15: =_xlfn.XLOOKUP(calls[[#This Row],[Customer ID]],customers[Customer ID],customers[City]) -> Cleveland | N15: =_xlfn.XLOOKUP(calls[[#This Row],[Customer ID]],customers[Customer ID],customers[Gedner]) -> Female | O15: 28 | P15: =IF(calls[[#This Row],[Call number]]<>"",1,0) -> 1 | Q15: =IF(calls[[#This Row],[Rating rounded]]=5,1,0) -> 0 | R15: C0012 | S15: Female | T15: 28 | U15: Cincinnati
... B18: Call_7285 | C18: C0013 | D18: 48 | E18: R01 | F18: 44930 | G18: 68 | H18: 4.9 | I18: =IF(MONTH(calls[[#This Row],[Date of Call]])<=6, YEAR(calls[[#This Row],[Date of Call]]), YEAR(calls[[#This Row],[Date of Call]])+1) -> 2023 | J18: =TEXT(calls[[#This Row],[Date of Call]],"DDDD") -> Wednesday | K18: {=_xlfn.IFS(calls[[#This Row],[Duration]]<=10,"Under 10 mins", calls[[#This Row],[Duration]]<=30, "10 to 30 mins", calls[[#This Row],[Duration]]<=60, "30 to 60 mins", calls[[#This Row],[Duration]]<=120, "1 to 2 hours", TRUE, "More than 2 hours")} -> 30 to 60 mins | L18: =ROUND(calls[[#This Row],[Satisfaction Rating]],0) -> 5 | M18: =_xlfn.XLOOKUP(calls[[#This Row],[Customer ID]],customers[Customer ID],customers[City]) -> Cleveland | N18: =_xlfn.XLOOKUP(calls[[#This Row],[Customer ID]],customers[Customer ID],customers[Gedner]) -> Female | O18: 43 | P18: =IF(calls[[#This Row],[Call number]]<>"",1,0) -> 1 | Q18: =IF(calls[[#This Row],[Rating rounded]]=5,1,0) -> 1 | R18: C0015 | S18: Female | T18: 43 | U18: Cleveland
B19: Call_7286 | C19: C0010 | D19: 176 | E19: R05 | F19: 44931 | G19: 24 | H19: 4.8 | I19: =IF(MONTH(calls[[#This Row],[Date of Call]])<=6, YEAR(calls[[#This Row],[Date of Call]]), YEAR(calls[[#This Row],[Date of Call]])+1) -> 2023 | J19: =TEXT(calls[[#This Row],[Date of Call]],"DDDD") -> Thursday | K19: {=_xlfn.IFS(calls[[#This Row],[Duration]]<=10,"Under 10 mins", calls[[#This Row],[Duration]]<=30, "10 to 30 mins", calls[[#This Row],[Duration]]<=60, "30 to 60 mins", calls[[#This Row],[Duration]]<=120, "1 to 2 hours", TRUE, "More than 2 hours")} -> More than 2 hours | L19: =ROUND(calls[[#This Row],[Satisfaction Rating]],0) -> 5 | M19: =_xlfn.XLOOKUP(calls[[#This Row],[Customer ID]],customers[Customer ID],customers[City]) -> Cleveland | N19: =_xlfn.XLOOKUP(calls[[#This Row],[Customer ID]],customers[Customer ID],customers[Gedner]) -> Female | P19: =IF(calls[[#This Row],[Call number]]<>"",1,0) -> 1 | Q19: =IF(calls[[#This Row],[Rating rounded]]=5,1,0) -> 1
B20: Call_7287 | C20: C0010 | D20: 99 | E20: R01 | F20: 44931 | G20: 195 | H20: 3.9 | I20: =IF(MONTH(calls[[#This Row],[Date of Call]])<=6, YEAR(calls[[#This Row],[Date of Call]]), YEAR(calls[[#This Row],[Date of Call]])+1) -> 2023 | J20: =TEXT(calls[[#This Row],[Date of Call]],"DDDD") -> Thursday | K20: {=_xlfn.IFS(calls[[#This Row],[Duration]]<=10,"Under 10 mins", calls[[#This Row],[Duration]]<=30, "10 to 30 mins", calls[[#This Row],[Duration]]<=60, "30 to 60 mins", calls[[#This Row],[Duration]]<=120, "1 to 2 hours", TRUE, "More than 2 hours")} -> 1 to 2 hours | L20: =ROUND(calls[[#This Row],[Satisfaction Rating]],0) -> 4 | M20: =_xlfn.XLOOKUP(calls[[#This Row],[Customer ID]],customers[Customer ID],customers[City]) -> Cleveland | N20: =_xlfn.XLOOKUP(calls[[#This Row],[Customer ID]],customers[Customer ID],customers[Gedner]) -> Female | P20: =IF(calls[[#This Row],[Call number]]<>"",1,0) -> 1 | Q20: =IF(calls[[#This Row],[Rating rounded]]=5,1,0) -> 0
B21: Call_7288 | C21: C0009 | D21: 28 | E21: R03 | F21: 44931 | G21: 28 | H21: 3.8 | I21: =IF(MONTH(calls[[#This Row],[Date of Call]])<=6, YEAR(calls[[#This Row],[Date of Call]]), YEAR(calls[[#This Row],[Date of Call]])+1) -> 2023 | J21: =TEXT(calls[[#This Row],[Date of Call]],"DDDD") -> Thursday | K21: {=_xlfn.IFS(calls[[#This Row],[Duration]]<=10,"Under 10 mins", calls[[#This Row],[Duration]]<=30, "10 to 30 mins", calls[[#This Row],[Duration]]<=60, "30 to 60 mins", calls[[#This Row],[Duration]]<=120, "1 to 2 hours", TRUE, "More than 2 hours")} -> 10 to 30 mins | L21: =ROUND(calls[[#This Row],[Satisfaction Rating]],0) -> 4 | M21: =_xlfn.XLOOKUP(calls[[#This Row],[Customer ID]],customers[Customer ID],customers[City]) -> Columbus | N21: =_xlfn.XLOOKUP(calls[[#This Row],[Customer ID]],customers[Customer ID],customers[Gedner]) -> Female | P21: =IF(calls[[#This Row],[Call number]]<>"",1,0) -> 1 | Q21: =IF(calls[[#This Row],[Rating rounded]]=5,1,0) -> 0
B22: Call_7289 | C22: C0007 | D22: 54 | E22: R02 | F22: 44931 | G22: 170 | H22: 4.3 | I22: =IF(MONTH(calls[[#This Row],[Date of Call]])<=6, YEAR(calls[[#This Row],[Date of Call]]), YEAR(calls[[#This Row],[Date of Call]])+1) -> 2023 | J22: =TEXT(calls[[#This Row],[Date of Call]],"DDDD") -> Thursday | K22: {=_xlfn.IFS(calls[[#This Row],[Duration]]<=10,"Under 10 mins", calls[[#This Row],[Duration]]<=30, "10 to 30 mins", calls[[#This Row],[Duration]]<=60, "30 to 60 mins", calls[[#This Row],[Duration]]<=120, "1 to 2 hours", TRUE, "More than 2 hours")} -> 30 to 60 mins | L22: =ROUND(calls[[#This Row],[Satisfaction Rating]],0) -> 4 | M22: =_xlfn.XLOOKUP(calls[[#This Row],[Customer ID]],customers[Customer ID],customers[City]) -> Cleveland | N22: =_xlfn.XLOOKUP(calls[[#This Row],[Customer ID]],customers[Customer ID],customers[Gedner]) -> Female | P22: =IF(calls[[#This Row],[Call number]]<>"",1,0) -> 1 | Q22: =IF(calls[[#This Row],[Rating rounded]]=5,1,0) -> 0
B23: Call_7290 | C23: C0006 | D23: 48 | E23: R05 | F23: 44932 | G23: 30 | H23: 4.4 | I23: =IF(MONTH(calls[[#This Row],[Date of Call]])<=6, YEAR(calls[[#This Row],[Date of Call]]), YEAR(calls[[#This Row],[Date of Call]])+1) -> 2023 | J23: =TEXT(calls[[#This Row],[Date of Call]],"DDDD") -> Friday | K23: {=_xlfn.IFS(calls[[#This Row],[Duration]]<=10,"Under 10 mins", calls[[#This Row],[Duration]]<=30, "10 to 30 mins", calls[[#This Row],[Duration]]<=60, "30 to 60 mins", calls[[#This Row],[Duration]]<=120, "1 to 2 hours", TRUE, "More than 2 hours")} -> 30 to 60 mins | L23: =ROUND(calls[[#This Row],[Satisfaction Rating]],0) -> 4 | M23: =_xlfn.XLOOKUP(calls[[#This Row],[Customer ID]],customers[Customer ID],customers[City]) -> Columbus | N23: =_xlfn.XLOOKUP(calls[[#This Row],[Customer ID]],customers[Customer ID],customers[Gedner]) -> Male | P23: =IF(calls[[#This Row],[Call number]]<>"",1,0) -> 1 | Q23: =IF(calls[[#This Row],[Rating rounded]]=5,1,0) -> 0
B24: Call_7291 | C24: C0004 | D24: 128 | E24: R05 | F24: 44932 | G24: 72 | H24: 5 | I24: =IF(MONTH(calls[[#This Row],[Date of Call]])<=6, YEAR(calls[[#This Row],[Date of Call]]), YEAR(calls[[#This Row],[Date of Call]])+1) -> 2023 | J24: =TEXT(calls[[#This Row],[Date of Call]],"DDDD") -> Friday | K24: {=_xlfn.IFS(calls[[#This Row],[Duration]]<=10,"Under 10 mins", calls[[#This Row],[Duration]]<=30, "10 to 30 mins", calls[[#This Row],[Duration]]<=60, "30 to 60 mins", calls[[#This Row],[Duration]]<=120, "1 to 2 hours", TRUE, "More than 2 hours")} -> More than 2 hours | L24: =ROUND(calls[[#This Row],[Satisfaction Rating]],0) -> 5 | M24: =_xlfn.XLOOKUP(calls[[#This Row],[Customer ID]],customers[Customer ID],customers[City]) -> Cincinnati | N24: =_xlfn.XLOOKUP(calls[[#This Row],[Customer ID]],customers[Customer ID],customers[Gedner]) -> Male | P24: =IF(calls[[#This Row],[Call number]]<>"",1,0) -> 1 | Q24: =IF(calls[[#This Row],[Rating rounded]]=5,1,0) -> 1
B25: Call_7292 | C25: C0004 | D25: 38 | E25: R04 | F25: 44933 | G25: 92 | H25: 4.9 | I25: =IF(MONTH(calls[[#This Row],[Date of Call]])<=6, YEAR(calls[[#This Row],[Date of Call]]), YEAR(calls[[#This Row],[Date of Call]])+1) -> 2023 | J25: =TEXT(calls[[#This Row],[Date of Call]],"DDDD") -> Saturday | K25: {=_xlfn.IFS(calls[[#This Row],[Duration]]<=10,"Under 10 mins", calls[[#This Row],[Duration]]<=30, "10 to 30 mins", calls[[#This Row],[Duration]]<=60, "30 to 60 mins", calls[[#This Row],[Duration]]<=120, "1 to 2 hours", TRUE, "More than 2 hours")} -> 30 to 60 mins | L25: =ROUND(calls[[#This Row],[Satisfaction Rating]],0) -> 5 | M25: =_xlfn.XLOOKUP(calls[[#This Row],[Customer ID]],customers[Customer ID],customers[City]) -> Cincinnati | N25: =_xlfn.XLOOKUP(calls[[#This Row],[Customer ID]],customers[Customer ID],customers[Gedner]) -> Male | P25: =IF(calls[[#This Row],[Call number]]<>"",1,0) -> 1 | Q25: =IF(calls[[#This Row],[Rating rounded]]=5,1,0) -> 1
B26: Call_7293 | C26: C0003 | D26: 67 | E26: R04 | F26: 44934 | G26: 165 | H26: 4.5 | I26: =IF(MONTH(calls[[#This Row],[Date of Call]])<=6, YEAR(calls[[#This Row],[Date of Call]]), YEAR(calls[[#This Row],[Date of Call]])+1) -> 2023 | J26: =TEXT(calls[[#This Row],[Date of Call]],"DDDD") -> Sunday | K26: {=_xlfn.IFS(calls[[#This Row],[Duration]]<=10,"Under 10 mins", calls[[#This Row],[Duration]]<=30, "10 to 30 mins", calls[[#This Row],[Duration]]<=60, "30 to 60 mins", calls[[#This Row],[Duration]]<=120, "1 to 2 hours", TRUE, "More than 2 hours")} -> 1 to 2 hours | L26: =ROUND(calls[[#This Row],[Satisfaction Rating]],0) -> 5 | M26: =_xlfn.XLOOKUP(calls[[#This Row],[Customer ID]],customers[Customer ID],customers[City]) -> Cincinnati | N26: =_xlfn.XLOOKUP(calls[[#This Row],[Customer ID]],customers[Customer ID],customers[Gedner]) -> Male | P26: =IF(calls[[#This Row],[Call number]]<>"",1,0) -> 1 | Q26: =IF(calls[[#This Row],[Rating rounded]]=5,1,0) -> 1
B27: Call_7294 | C27: C0015 | D27: 58 | E27: R02 | F27: 44934 | G27: 140 | H27: 2.1 | I27: =IF(MONTH(calls[[#This Row],[Date of Call]])<=6, YEAR(calls[[#This Row],[Date of Call]]), YEAR(calls[[#This Row],[Date of Call]])+1) -> 2023 | J27: =TEXT(calls[[#This Row],[Date of Call]],"DDDD") -> Sunday | K27: {=_xlfn.IFS(calls[[#This Row],[Duration]]<=10,"Under 10 mins", calls[[#This Row],[Duration]]<=30, "10 to 30 mins", calls[[#This Row],[Duration]]<=60, "30 to 60 mins", calls[[#This Row],[Duration]]<=120, "1 to 2 hours", TRUE, "More than 2 hours")} -> 30 to 60 mins | L27: =ROUND(calls[[#This Row],[Satisfaction Rating]],0) -> 2 | M27: =_xlfn.XLOOKUP(calls[[#This Row],[Customer ID]],customers[Customer ID],customers[City]) -> Cleveland | N27: =_xlfn.XLOOKUP(calls[[#This Row],[Customer ID]],customers[Customer ID],customers[Gedner]) -> Female | P27: =IF(calls[[#This Row],[Call number]]<>"",1,0) -> 1 | Q27: =IF(calls[[#This Row],[Rating rounded]]=5,1,0) -> 0
B28: Call_7295 | C28: C0010 | D28: 54 | E28: R01 | F28: 44934 | G28: 111 | H28: 3.3 | I28: =IF(MONTH(calls[[#This Row],[Date of Call]])<=6, YEAR(calls[[#This Row],[Date of Call]]), YEAR(calls[[#This Row],[Date of Call]])+1) -> 2023 | J28: =TEXT(calls[[#This Row],[Date of Call]],"DDDD") -> Sunday | K28: {=_xlfn.IFS(calls[[#This Row],[Duration]]<=10,"Under 10 mins", calls[[#This Row],[Duration]]<=30, "10 to 30 mins", calls[[#This Row],[Duration]]<=60, "30 to 60 mins", calls[[#This Row],[Duration]]<=120, "1 to 2 hours", TRUE, "More than 2 hours")} -> 30 to 60 mins | L28: =ROUND(calls[[#This Row],[Satisfaction Rating]],0) -> 3 | M28: =_xlfn.XLOOKUP(calls[[#This Row],[Customer ID]],customers[Customer ID],customers[City]) -> Cleveland | N28: =_xlfn.XLOOKUP(calls[[#This Row],[Customer ID]],customers[Customer ID],customers[Gedner]) -> Female | P28: =IF(calls[[#This Row],[Call number]]<>"",1,0) -> 1 | Q28: =IF(calls[[#This Row],[Rating rounded]]=5,1,0) -> 0
B29: Call_7296 | C29: C0012 | D29: 28 | E29: R05 | F29: 44935 | G29: 63 | H29: 4.1 | I29: =IF(MONTH(calls[[#This Row],[Date of Call]])<=6, YEAR(calls[[#This Row],[Date of Call]]), YEAR(calls[[#This Row],[Date of Call]])+1) -> 2023 | J29: =TEXT(calls[[#This Row],[Date of Call]],"DDDD") -> Monday | K29: {=_xlfn.IFS(calls[[#This Row],[Duration]]<=10,"Under 10 mins", calls[[#This Row],[Duration]]<=30, "10 to 30 mins", calls[[#This Row],[Duration]]<=60, "30 to 60 mins", calls[[#This Row],[Duration]]<=120, "1 to 2 hours", TRUE, "More than 2 hours")} -> 10 to 30 mins | L29: =ROUND(calls[[#This Row],[Satisfaction Rating]],0) -> 4 | M29: =_xlfn.XLOOKUP(calls[[#This Row],[Customer ID]],customers[Customer ID],customers[City]) -> Cincinnati | N29: =_xlfn.XLOOKUP(calls[[#This Row],[Customer ID]],customers[Customer ID],customers[Gedner]) -> Female | P29: =IF(calls[[#This Row],[Call number]]<>"",1,0) -> 1 | Q29: =IF(calls[[#This Row],[Rating rounded]]=5,1,0) -> 0
B30: Call_7297 | C30: C0002 | D30: 73 | E30: R05 | F30: 44935 | G30: 80 | H30: 4.2 | I30: =IF(MONTH(calls[[#This Row],[Date of Call]])<=6, YEAR(calls[[#This Row],[Date of Call]]), YEAR(calls[[#This Row],[Date of Call]])+1) -> 2023 | J30: =TEXT(calls[[#This Row],[Date of Call]],"DDDD") -> Monday | K30: {=_xlfn.IFS(calls[[#This Row],[Duration]]<=10,"Under 10 mins", calls[[#This Row],[Duration]]<=30, "10 to 30 mins", calls[[#This Row],[Duration]]<=60, "30 to 60 mins", calls[[#This Row],[Duration]]<=120, "1 to 2 hours", TRUE, "More than 2 hours")} -> 1 to 2 hours | L30: =ROUND(calls[[#This Row],[Satisfaction Rating]],0) -> 4 | M30: =_xlfn.XLOOKUP(calls[[#This Row],[Customer ID]],customers[Customer ID],customers[City]) -> Cleveland | N30: =_xlfn.XLOOKUP(calls[[#This Row],[Customer ID]],customers[Customer ID],customers[Gedner]) -> Male | P30: =IF(calls[[#This Row],[Call number]]<>"",1,0) -> 1 | Q30: =IF(calls[[#This Row],[Rating rounded]]=5,1,0) -> 0
... B1003: Call_8270 | C1003: C0009 | D1003: 114 | E1003: R01 | F1003: 45291 | G1003: 40 | H1003: 3.9 | I1003: =IF(MONTH(calls[[#This Row],[Date of Call]])<=6, YEAR(calls[[#This Row],[Date of Call]]), YEAR(calls[[#This Row],[Date of Call]])+1) -> 2024 | J1003: =TEXT(calls[[#This Row],[Date of Call]],"DDDD") -> Sunday | K1003: {=_xlfn.IFS(calls[[#This Row],[Duration]]<=10,"Under 10 mins", calls[[#This Row],[Duration]]<=30, "10 to 30 mins", calls[[#This Row],[Duration]]<=60, "30 to 60 mins", calls[[#This Row],[Duration]]<=120, "1 to 2 hours", TRUE, "More than 2 hours")} -> 1 to 2 hours | L1003: =ROUND(calls[[#This Row],[Satisfaction Rating]],0) -> 4 | M1003: =_xlfn.XLOOKUP(calls[[#This Row],[Customer ID]],customers[Customer ID],customers[City]) -> Columbus | N1003: =_xlfn.XLOOKUP(calls[[#This Row],[Customer ID]],customers[Customer ID],customers[Gedner]) -> Female | P1003: =IF(calls[[#This Row],[Call number]]<>"",1,0) -> 1 | Q1003: =IF(calls[[#This Row],[Rating rounded]]=5,1,0) -> 0

Sheet Dashboard
Q23: R1 | R23: R2 | S23: R3 | T23: R4 | U23: R5 | V23: TOTAL
P24: {=IF(Sheet4!D109:J126="","",Sheet4!D109:J126)} -> Cincinnati
P25: C0003 | Q25: 891 | R25: 1332 | S25: 1282 | T25: 739 | U25: 560 | V25: 4804
P26: C0004 | Q26: 1991 | R26: 1886 | S26: 1206 | T26: 884 | U26: 1722 | V26: 7689
P27: C0011 | Q27: 1163 | R27: 1180 | S27: 1616 | T27: 1043 | U27: 1747 | V27: 6749
P28: C0012 | Q28: 1438 | R28: 1616 | S28: 866 | T28: 829 | U28: 2070 | V28: 6819
P29: Cleveland
P30: C0002 | Q30: 1233 | R30: 223 | S30: 1680 | T30: 990 | U30: 1508 | V30: 5634
P31: C0007 | Q31: 1598 | R31: 1907 | S31: 869 | T31: 1426 | U31: 1416 | V31: 7216
P32: C0008 | Q32: 900 | R32: 1016 | S32: 960 | T32: 940 | U32: 1193 | V32: 5009
P33: C0010 | Q33: 900 | R33: 1470 | S33: 1617 | T33: 1314 | U33: 941 | V33: 6242
P34: C0013 | Q34: 1255 | R34: 516 | S34: 1874 | T34: 1863 | U34: 1722 | V34: 7230
P35: C0015 | Q35: 1138 | R35: 1898 | S35: 1482 | T35: 846 | U35: 1154 | V35: 6518
P36: Columbus
M37: =Sheet4!I83 -> #VALUE! | P37: C0001 | Q37: 1655 | R37: 805 | S37: 2263 | T37: 987 | U37: 1075 | V37: 6785
P38: C0005 | Q38: 1104 | R38: 2280 | S38: 1445 | T38: 1722 | U38: 1196 | V38: 7747
P39: C0006 | Q39: 372 | R39: 1818 | S39: 1346 | T39: 1156 | U39: 1484 | V39: 6176
P40: C0009 | Q40: 1415 | R40: 1271 | S40: 1214 | T40: 1135 | U40: 1566 | V40: 6601
P41: C0014 | Q41: 1362 | R41: 1363 | S41: 1152 | T41: 777 | U41: 750 | V41: 5404
M42: =Sheet4!I78 -> % of calls:19%
M43: =Sheet4!I79 -> call rank:4
M44: =Sheet4!I80 -> Amount rank:4

Sheet Assets
E2: Rep ID | F2: Rep Image
E3: R01 | F3: #VALUE!
E4: R02 | F4: #VALUE!
E5: R03 | F5: #VALUE!
E6: R04 | F6: #VALUE!
E7: R05 | F7: #VALUE!
